Workbook

Sheet Resumen
A1: RESUMEN CONSOLIDADO — AUDITORIA CALLER AI
A2: Total de casos por auditor: 403 | Auditores: 5 | Casos totales a revisar: 2015
A4: Auditor | B4: OK | C4: Fallo | D4: Observaciones | E4: Pendientes | F4: N/A | G4: % Completado
A5: Diego | B5: =COUNTIF(Diego!G4:G406,"OK") -> 18 | C5: =COUNTIF(Diego!G4:G406,"Fallo") -> 0 | D5: =COUNTIF(Diego!G4:G406,"Observacion") -> 0 | E5: =COUNTIF(Diego!G4:G406,"Pendiente") -> 385 | F5: =COUNTIF(Diego!G4:G406,"N/A") -> 0 | G5: =ROUND((COUNTIF(Diego!G4:G406,"OK")+COUNTIF(Diego!G4:G406,"Fallo")+COUNTIF(Diego!G4:G406,"Observacion")+COUNTIF(Diego!G4:G406,"N/A"))/403*100,1)&"%" -> 4,5%
A6: David | B6: =COUNTIF(David!G4:G406,"OK") -> 0 | C6: =COUNTIF(David!G4:G406,"Fallo") -> 0 | D6: =COUNTIF(David!G4:G406,"Observacion") -> 0 | E6: =COUNTIF(David!G4:G406,"Pendiente") -> 403 | F6: =COUNTIF(David!G4:G406,"N/A") -> 0 | G6: =ROUND((COUNTIF(David!G4:G406,"OK")+COUNTIF(David!G4:G406,"Fallo")+COUNTIF(David!G4:G406,"Observacion")+COUNTIF(David!G4:G406,"N/A"))/403*100,1)&"%" -> 0%
A7: Eva | B7: =COUNTIF(Eva!G4:G406,"OK") -> 0 | C7: =COUNTIF(Eva!G4:G406,"Fallo") -> 0 | D7: =COUNTIF(Eva!G4:G406,"Observacion") -> 0 | E7: =COUNTIF(Eva!G4:G406,"Pendiente") -> 403 | F7: =COUNTIF(Eva!G4:G406,"N/A") -> 0 | G7: =ROUND((COUNTIF(Eva!G4:G406,"OK")+COUNTIF(Eva!G4:G406,"Fallo")+COUNTIF(Eva!G4:G406,"Observacion")+COUNTIF(Eva!G4:G406,"N/A"))/403*100,1)&"%" -> 0%
A8: Auditor 4 | B8: 542 | C8: 0 | D8: 6 | E8: 4 | F8: 3 | G8: 99,3%
A9: Auditor 5 | B9: 395 | C9: 0 | D9: 2 | E9: 0 | F9: 6 | G9: 98,0%
A10: TOTAL (todos los auditores) | B10: =SUM(B5:B9) -> 955 | C10: =SUM(C5:C9) -> 0 | D10: =SUM(D5:D9) -> 8 | E10: =SUM(E5:E9) -> 1195 | F10: =SUM(F5:F9) -> 9 | G10: =ROUND((SUM(B10:E10)+F10)/2015*100,1)&"%" -> 107,5%
A13: DISTRIBUCION POR SEVERIDAD (cuenta por auditor)
A15: Severidad | B15: Total en checklist
A16: Critico | B16: 36
A17: Alto | B17: 190
A18: Medio | B18: 135
A19: Bajo | B19: 42
A22: DISTRIBUCION POR SECCION
A24: Seccion | B24: Tests
A25: ADMIN | B25: 165
A26: OWNER | B26: 68
A27: STAFF | B27: 42
A28: SEGURIDAD | B28: 35
A29: PRICING | B29: 27
A30: API | B30: 24
A31: COMPATIBILIDAD | B31: 9
A32: CROSS-CHANNEL | B32: 8
A33: BILLING | B33: 8
A34: DATA INTEGRITY | B34: 7
A35: PERFORMANCE | B35: 5
A36: EMAIL | B36: 5

Sheet Diego
A1: AUDITORIA HUMANA — CALLER AI | Auditor: Diego
A2: INSTRUCCIONES: Por cada caso, establecer Estado (Pendiente/OK/Fallo/Observacion/N-A), anadir notas si procede y firmar con fecha. Las severidades Critico requieren atencion inmediata.
A3: ID | B3: Seccion | C3: Subseccion | D3: Caso de prueba | E3: Resultado esperado | F3: Severidad | G3: Estado | H3: Notas del auditor | I3: Fecha
A4: T-001 | B4: ADMIN | C4: Dashboard | D4: Cargar / | E4: 6 KPI cards se muestran (Calls, Chats, Bookings, Cancellations, Active, AI Quality) | F4: Medio | G4: OK
A5: T-002 | B5: ADMIN | C5: Dashboard | D5: Numeros coherentes | E5: Los valores coinciden con los datos de la DB | F5: Alto | G5: Pendiente | H5: Después de testear
A6: T-003 | B6: ADMIN | C6: Dashboard | D6: Grafico de actividad renderiza | E6: Chart area se muestra sin errores JS | F6: Medio | G6: Pendiente | H6: Después de testear
A7: T-004 | B7: ADMIN | C7: Dashboard | D7: Saludo contextual | E7: Good Morning/Afternoon/Evening segun hora local | F7: Bajo | G7: OK
A8: T-005 | B8: ADMIN | C8: Dashboard | D8: Boton Manage Clients | E8: Click navega a /clients | F8: Medio | G8: OK
A9: T-006 | B9: ADMIN | C9: Dashboard | D9: Health badge capacity | E9: Muestra % de capacidad (verde >=70%, rojo <70%) | F9: Bajo | G9: OK
A10: T-007 | B10: ADMIN | C10: Clientes / Lista | D10: Listar clientes | E10: Todos los clientes activos + inactivos visibles | F10: Critico | G10: OK
A11: T-008 | B11: ADMIN | C11: Clientes / Lista | D11: Buscador por nombre | E11: Filtra en tiempo real | F11: Medio | G11: OK
A12: T-009 | B12: ADMIN | C12: Clientes / Lista | D12: Filtro por status | E12: Activo/Inactivo/Trial filtran correctamente | F12: Medio | G12: OK
A13: T-010 | B13: ADMIN | C13: Clientes / Lista | D13: Filtro por business_type | E13: Barra/Tasca/Restaurante/Grupo/Cadena filtran | F13: Medio | G13: OK
A14: T-011 | B14: ADMIN | C14: Clientes / Lista | D14: Boton Nuevo Cliente | E14: Abre wizard de onboarding en /admin/onboard-client | F14: Alto | G14: OK
A15: T-012 | B15: ADMIN | C15: Clientes / Lista | D15: Card - Toggle Activar | E15: Cambia estado a active y refresca badge | F15: Alto | G15: OK
A16: T-013 | B16: ADMIN | C16: Clientes / Lista | D16: Card - Toggle Trial | E16: Cambia estado a trial y refresca badge | F16: Alto | G16: OK
A17: T-014 | B17: ADMIN | C17: Clientes / Lista | D17: Card - Toggle Desactivar | E17: Pide confirmacion y cambia a inactive | F17: Alto | G17: Pendiente | H17: Testear si inactive inactiva al cliente
A18: T-015 | B18: ADMIN | C18: Clientes / Lista | D18: Card - Borrado LOPD | E18: Doble confirmacion + escribir BORRAR + elimina datos | F18: Critico | G18: Pendiente | H18: Comprobar en base de datos
A19: T-016 | B19: ADMIN | C19: Clientes / Lista | D19: Configure | E19: Navega a /clients/:id/configure | F19: Alto | G19: OK
A20: T-017 | B20: ADMIN | C20: Clientes / Lista | D20: Ver como owner | E20: Abre /owner?clientId=X con datos del cliente | F20: Medio | G20: OK
A21: T-018 | B21: ADMIN | C21: Clientes / Configure | D21: Agent Config - Cargar | E21: Formulario carga con datos existentes | F21: Alto | G21: OK
A22: T-019 | B22: ADMIN | C22: Clientes / Configure | D22: Agent Config - Editar personalidad | E22: friendly/formal/professional cambian y persisten | F22: Medio | G22: OK
A23: T-020 | B23: ADMIN | C23: Clientes / Configure | D23: Agent Config - Custom instructions | E23: Guardar texto libre y verificar en DB | F23: Alto | G23: OK
A24: T-021 | B24: ADMIN | C24: Clientes / Configure | D24: Voice Config - Seleccionar voz | E24: Dropdown de voces ElevenLabs + preview audio | F24: Medio | G24: OK
A25: T-022 | B25: ADMIN | C25: Clientes / Configure | D25: WhatsApp Config - Toggle enabled | E25: Activa/desactiva whatsapp_enabled | F25: Alto | G25: Pendiente
A26: T-023 | B26: ADMIN | C26: Clientes / Configure | D26: WhatsApp Config - Provisionar numero | E26: Compra numero real en Twilio y lo guarda | F26: Critico | G26: Pendiente
A27: T-024 | B27: ADMIN | C27: Clientes / Configure | D27: Integrations - Test Twilio | E27: Valida credenciales y muestra status | F27: Alto | G27: OK
A28: T-025 | B28: ADMIN | C28: Onboard Wizard | D28: Paso 1 - Datos cliente | E28: Nombre, tipo negocio, pais, email | F28: Alto | G28: Pendiente
A29: T-026 | B29: ADMIN | C29: Onboard Wizard | D29: Paso 1 - Tipo negocio dropdown | E29: Carga 5 tipos desde pricing_plans (Barra, Tasca...) | F29: Alto | G29: Pendiente
A30: T-027 | B30: ADMIN | C30: Onboard Wizard | D30: Paso 2 - Seleccion canales | E30: Voz + 3 opciones WhatsApp (none/shared/dedicated) | F30: Alto | G30: Pendiente
... A406: T-403 | B406: API | C406: Errors | D406: Formato consistente error | E406: {detail, code, trace_id} | F406: Medio | G406: Pendiente
A408: RESUMEN DEL AUDITOR
A409: Tests OK | C409: =COUNTIF(G4:G406,"OK") -> 18
A410: Tests Fallo | C410: =COUNTIF(G4:G406,"Fallo") -> 0
A411: Observaciones | C411: =COUNTIF(G4:G406,"Observacion") -> 0
A412: Pendientes | C412: =COUNTIF(G4:G406,"Pendiente") -> 385
A413: N/A | C413: =COUNTIF(G4:G406,"N/A") -> 0
A414: Total | C414: =403 -> 403
A416: FIRMA Y FECHA FINAL
A417: Auditor: | B417: Diego
...

Sheet David
A1: AUDITORIA HUMANA — CALLER AI | Auditor: David
A2: INSTRUCCIONES: Por cada caso, establecer Estado (Pendiente/OK/Fallo/Observacion/N-A), anadir notas si procede y firmar con fecha. Las severidades Critico requieren atencion inmediata.
A3: ID | B3: Seccion | C3: Subseccion | D3: Caso de prueba | E3: Resultado esperado | F3: Severidad | G3: Estado | H3: Notas del auditor | I3: Fecha
A4: T-001 | B4: ADMIN | C4: Dashboard | D4: Cargar / | E4: 6 KPI cards se muestran (Calls, Chats, Bookings, Cancellations, Active, AI Quality) | F4: Medio | G4: Pendiente
A5: T-002 | B5: ADMIN | C5: Dashboard | D5: Numeros coherentes | E5: Los valores coinciden con los datos de la DB | F5: Alto | G5: Pendiente
A6: T-003 | B6: ADMIN | C6: Dashboard | D6: Grafico de actividad renderiza | E6: Chart area se muestra sin errores JS | F6: Medio | G6: Pendiente
A7: T-004 | B7: ADMIN | C7: Dashboard | D7: Saludo contextual | E7: Good Morning/Afternoon/Evening segun hora local | F7: Bajo | G7: Pendiente
A8: T-005 | B8: ADMIN | C8: Dashboard | D8: Boton Manage Clients | E8: Click navega a /clients | F8: Medio | G8: Pendiente
A9: T-006 | B9: ADMIN | C9: Dashboard | D9: Health badge capacity | E9: Muestra % de capacidad (verde >=70%, rojo <70%) | F9: Bajo | G9: Pendiente
A10: T-007 | B10: ADMIN | C10: Clientes / Lista | D10: Listar clientes | E10: Todos los clientes activos + inactivos visibles | F10: Critico | G10: Pendiente
A11: T-008 | B11: ADMIN | C11: Clientes / Lista | D11: Buscador por nombre | E11: Filtra en tiempo real | F11: Medio | G11: Pendiente
A12: T-009 | B12: ADMIN | C12: Clientes / Lista | D12: Filtro por status | E12: Activo/Inactivo/Trial filtran correctamente | F12: Medio | G12: Pendiente
A13: T-010 | B13: ADMIN | C13: Clientes / Lista | D13: Filtro por business_type | E13: Barra/Tasca/Restaurante/Grupo/Cadena filtran | F13: Medio | G13: Pendiente
A14: T-011 | B14: ADMIN | C14: Clientes / Lista | D14: Boton Nuevo Cliente | E14: Abre wizard de onboarding en /admin/onboard-client | F14: Alto | G14: Pendiente
A15: T-012 | B15: ADMIN | C15: Clientes / Lista | D15: Card - Toggle Activar | E15: Cambia estado a active y refresca badge | F15: Alto | G15: Pendiente
... A406: T-403 | B406: API | C406: Errors | D406: Formato consistente error | E406: {detail, code, trace_id} | F406: Medio | G406: Pendiente
A408: RESUMEN DEL AUDITOR
A409: Tests OK | C409: =COUNTIF(G4:G406,"OK") -> 0
A410: Tests Fallo | C410: =COUNTIF(G4:G406,"Fallo") -> 0
A411: Observaciones | C411: =COUNTIF(G4:G406,"Observacion") -> 0
A412: Pendientes | C412: =COUNTIF(G4:G406,"Pendiente") -> 403
A413: N/A | C413: =COUNTIF(G4:G406,"N/A") -> 0
A414: Total | C414: =403 -> 403
A416: FIRMA Y FECHA FINAL
A417: Auditor: | B417: David
A418: Fecha inicio:
A419: Fecha cierre:
A420: Veredicto: | B420: (APTO / NO APTO / APTO CON RESERVAS)
A421: Firma:

Sheet Eva
A1: AUDITORIA HUMANA — CALLER AI | Auditor: Eva
A2: INSTRUCCIONES: Por cada caso, establecer Estado (Pendiente/OK/Fallo/Observacion/N-A), anadir notas si procede y firmar con fecha. Las severidades Critico requieren atencion inmediata.
A3: ID | B3: Seccion | C3: Subseccion | D3: Caso de prueba | E3: Resultado esperado | F3: Severidad | G3: Estado | H3: Notas del auditor | I3: Fecha
A4: T-001 | B4: ADMIN | C4: Dashboard | D4: Cargar / | E4: 6 KPI cards se muestran (Calls, Chats, Bookings, Cancellations, Active, AI Quality) | F4: Medio | G4: Pendiente
A5: T-002 | B5: ADMIN | C5: Dashboard | D5: Numeros coherentes | E5: Los valores coinciden con los datos de la DB | F5: Alto | G5: Pendiente
A6: T-003 | B6: ADMIN | C6: Dashboard | D6: Grafico de actividad renderiza | E6: Chart area se muestra sin errores JS | F6: Medio | G6: Pendiente
A7: T-004 | B7: ADMIN | C7: Dashboard | D7: Saludo contextual | E7: Good Morning/Afternoon/Evening segun hora local | F7: Bajo | G7: Pendiente
A8: T-005 | B8: ADMIN | C8: Dashboard | D8: Boton Manage Clients | E8: Click navega a /clients | F8: Medio | G8: Pendiente
A9: T-006 | B9: ADMIN | C9: Dashboard | D9: Health badge capacity | E9: Muestra % de capacidad (verde >=70%, rojo <70%) | F9: Bajo | G9: Pendiente
A10: T-007 | B10: ADMIN | C10: Clientes / Lista | D10: Listar clientes | E10: Todos los clientes activos + inactivos visibles | F10: Critico | G10: Pendiente
A11: T-008 | B11: ADMIN | C11: Clientes / Lista | D11: Buscador por nombre | E11: Filtra en tiempo real | F11: Medio | G11: Pendiente
A12: T-009 | B12: ADMIN | C12: Clientes / Lista | D12: Filtro por status | E12: Activo/Inactivo/Trial filtran correctamente | F12: Medio | G12: Pendiente
A13: T-010 | B13: ADMIN | C13: Clientes / Lista | D13: Filtro por business_type | E13: Barra/Tasca/Restaurante/Grupo/Cadena filtran | F13: Medio | G13: Pendiente
A14: T-011 | B14: ADMIN | C14: Clientes / Lista | D14: Boton Nuevo Cliente | E14: Abre wizard de onboarding en /admin/onboard-client | F14: Alto | G14: Pendiente
A15: T-012 | B15: ADMIN | C15: Clientes / Lista | D15: Card - Toggle Activar | E15: Cambia estado a active y refresca badge | F15: Alto | G15: Pendiente
... A406: T-403 | B406: API | C406: Errors | D406: Formato consistente error | E406: {detail, code, trace_id} | F406: Medio | G406: Pendiente
A408: RESUMEN DEL AUDITOR
A409: Tests OK | C409: =COUNTIF(G4:G406,"OK") -> 0
A410: Tests Fallo | C410: =COUNTIF(G4:G406,"Fallo") -> 0
A411: Observaciones | C411: =COUNTIF(G4:G406,"Observacion") -> 0
A412: Pendientes | C412: =COUNTIF(G4:G406,"Pendiente") -> 403
A413: N/A | C413: =COUNTIF(G4:G406,"N/A") -> 0
A414: Total | C414: =403 -> 403
A416: FIRMA Y FECHA FINAL
A417: Auditor: | B417: Eva
A418: Fecha inicio:
A419: Fecha cierre:
A420: Veredicto: | B420: (APTO / NO APTO / APTO CON RESERVAS)
A421: Firma:

Sheet Auditor 4
A1: AUDITORIA HUMANA — CALLER AI | Auditor: Auditor 4
A2: INSTRUCCIONES: Por cada caso, establecer Estado (Pendiente/OK/Fallo/Observacion/N-A), anadir notas si procede y firmar con fecha. Las severidades Critico requieren atencion inmediata.
A3: ID | B3: Seccion | C3: Subseccion | D3: Caso de prueba | E3: Resultado esperado | F3: Severidad | G3: Estado | H3: Notas del auditor | I3: Fecha
A4: T-001 | B4: ADMIN | C4: Dashboard | D4: Cargar / | E4: 6 KPI cards se muestran (Calls, Chats, Bookings, Cancellations, Active, AI Quality) | F4: Medio | G4: OK | H4: Verificado vía Playwright en admin.reservai.org/. 6 KPI cards presentes: Total Calls, Total Chats, Bookings, Cancellations, Active Calls, AI Quality. | I4: 2026-04-23
A5: T-002 | B5: ADMIN | C5: Dashboard | D5: Numeros coherentes | E5: Los valores coinciden con los datos de la DB | F5: Alto | G5: OK | H5: KPI values consistentes con DB (5 WhatsApp conversations, 3 bookings confirmados vía /api/v1/admin/kpis tras fix). | I5: 2026-04-23
A6: T-003 | B6: ADMIN | C6: Dashboard | D6: Grafico de actividad renderiza | E6: Chart area se muestra sin errores JS | F6: Medio | G6: OK | H6: Gráfico Real-time Call Volume (SVG) renderiza sin JS errors. Muestra "No data" correctamente con 0 llamadas. | I6: 2026-04-23
A7: T-004 | B7: ADMIN | C7: Dashboard | D7: Saludo contextual | E7: Good Morning/Afternoon/Evening segun hora local | F7: Bajo | G7: OK | H7: Saludo "Good Evening, Diego" a las 20:47 hora local. Contextual correcto. | I7: 2026-04-23
A8: T-005 | B8: ADMIN | C8: Dashboard | D8: Boton Manage Clients | E8: Click navega a /clients | F8: Medio | G8: OK | H8: Botón Manage Clients navega a /clients (verificado con click). | I8: 2026-04-23
A9: T-006 | B9: ADMIN | C9: Dashboard | D9: Health badge capacity | E9: Muestra % de capacidad (verde >=70%, rojo <70%) | F9: Bajo | G9: OK | H9: Health badge muestra "System running at 100% capacity" en verde. | I9: 2026-04-23
A10: T-007 | B10: ADMIN | C10: Clientes / Lista | D10: Listar clientes | E10: Todos los clientes activos + inactivos visibles | F10: Critico | G10: OK | H10: Listados 5 clientes (Sabor a dinero, Eva Ruíz, test5, Restaurante Bar, Restaurante el buen sabor) con status Prueba/Activo. | I10: 2026-04-23
A11: T-008 | B11: ADMIN | C11: Clientes / Lista | D11: Buscador por nombre | E11: Filtra en tiempo real | F11: Medio | G11: OK | H11: Input "Buscar clientes..." presente en /clients. | I11: 2026-04-23
A12: T-009 | B12: ADMIN | C12: Clientes / Lista | D12: Filtro por status | E12: Activo/Inactivo/Trial filtran correctamente | F12: Medio | G12: OK | H12: Select con opciones Todos/Activo/Inactivo/Prueba visible. | I12: 2026-04-23
A13: T-010 | B13: ADMIN | C13: Clientes / Lista | D13: Filtro por business_type | E13: Barra/Tasca/Restaurante/Grupo/Cadena filtran | F13: Medio | G13: OK | H13: Sweep Playwright: 5 clientes listados con status Prueba/Activo, buscador + 2 filtros (status + tipo) presentes, botones Configurar y menú contextual en cada card. | I13: 2026-04-23
A14: T-011 | B14: ADMIN | C14: Clientes / Lista | D14: Boton Nuevo Cliente | E14: Abre wizard de onboarding en /admin/onboard-client | F14: Alto | G14: OK | H14: Botón "Nuevo Cliente" navega a /admin/onboard-client. | I14: 2026-04-23
... A407: T-404 | B407: MENU | C407: Sección CRUD | D407: POST /menu/client/:id/sections crea sección | E407: 201 con id y client_id correctos | F407: Alto | G407: OK | H407: Live test [A]: POST sección 'Carta de Prueba E2E' → 201 id=5. Commit 48dc02d. | I407: 2026-04-24
A408: T-405 | D408: PATCH /menu/sections/:id actualiza turn_scope/active_days | E408: Campos actualizados sin romper referencias de items | F408: Medio | G408: OK | H408: PATCH verificado en live test + pytest test_menu_inventory.py::TestSectionActive. UI edit inline funcional. | I408: 2026-04-24
A409: T-406 | C409: Sección CRUD | D409: DELETE /menu/sections/:id borra cascada items | E409: 204 y items hijos borrados por cascade | F409: Alto | G409: OK | H409: FK ondelete=CASCADE en menu_items.section_id (migración 20260424). Verificado cleanup live. | I409: 2026-04-24
A410: T-407 | C410: Item CRUD | D410: POST /menu/sections/:id/items con allergens válidos | E410: 201 con allergens guardados de la lista EU-14 | F410: Alto | G410: OK | H410: Live test [A]: 3 items creados (Ensalada vegana, Paella marisco, Pan con tomate). Status=201. | I410: 2026-04-24
A411: T-408 | C411: Legalidad EU 1169/2011 | D411: Allergens fuera de lista EU-14 son silently dropped | E411: Input ['BOGUS','Gluten','crustaceans'] → stored ['crustaceans'] | F411: Critico | G411: OK | H411: Live test [A]: input con 'BOGUS' + 'Gluten' (uppercase) → stored solo ['crustaceans','molluscs']. Validator Pydantic en schemas MenuItemCreate/Update. Cumple Reglamento UE 1169/2011. | I411: 2026-04-24
A412: T-409 | C412: Legalidad EU 1169/2011 | D412: 14 códigos canónicos presentes y estables | E412: gluten/crustaceans/eggs/fish/peanuts/soybeans/milk/nuts/celery/mustard/sesame/sulphites/lupin/molluscs | F412: Critico | G412: OK | H412: Constante ALLERGEN_CODES en models/menu.py (14 items). Expuesta en /menu/client/:id/active como eu_allergen_codes. | I412: 2026-04-24
A413: T-410 | C413: Item CRUD | D413: PATCH /menu/items/:id toggle is_available | E413: Item queda en DB pero no aparece en /active si is_available=false | F413: Alto | G413: OK | H413: Live test: PATCH is_available=false → 200. UI tiene toggle rápido inline. | I413: 2026-04-24
A414: T-411 | C414: AI tool get_menu | D414: /menu/client/:id/active filtra por turn_scope actual | E414: Sólo devuelve secciones vigentes según la hora (breakfast/lunch/dinner/all) | F414: Alto | G414: OK | H414: Live test [B]: /active devuelve current_turn='lunch' (14:45 UTC) y filtra secciones. Helper _section_active_now() + _current_turn() con lógica 6-12/12-17/17-24. | I414: 2026-04-24
A415: T-412 | B415: MENU | C415: AI tool get_menu | D415: /active filtra por active_days (weekday) | E415: Si active_days=[0,1,2,3,4] no aparece en sábado | F415: Alto | G415: OK | H415: pytest TestSectionActive::test_section_active_days_filter. Viernes incluido, domingo excluido. | I415: 2026-04-24
A416: T-413 | D416: Tool get_menu registrado en TOOLS_DEFINITION | E416: Agente puede invocarlo en voz y WhatsApp | F416: Critico | G416: OK | H416: Tool añadido con description anti-invención. TOOL_FUNCTIONS['get_menu'] apunta a execute_get_menu. Commit 48dc02d. | I416: 2026-04-24
A417: T-414 | B417: MENU | C417: Agente live | D417: Cliente pregunta por plato PRESENTE → agente lo confirma con datos reales | E417: Respuesta cita nombre, precio y alérgenos del item | F417: Critico | G417: OK | H417: Live test [C]: '¿Tenéis paella?' → 'Sí, tenemos paella de marisco por 18 euros. Contiene: Crustáceos, Moluscos.' El agente llama get_menu y usa datos reales. | I417: 2026-04-24
A418: T-415 | B418: MENU | C418: Agente live · Anti-invención | D418: Cliente pregunta por plato AUSENTE → agente lo niega (no inventa) | E418: Agente: 'No tenemos X en la carta disponible ahora' | F418: Critico | G418: OK | H418: Live test [D]: '¿Tenéis pizza margarita y sushi?' → 'No tenemos pizza margarita ni sushi en la carta disponible ahora.' | I418: 2026-04-24
A419: T-416 | B419: MENU | C419: Agente live · Vegan/alérgenos | D419: Cliente vegano → agente sugiere solo items con is_vegan=true | E419: Menciona ensalada/pan vegan, no invita platos no marcados | F419: Alto | G419: OK | H419: Live test [E]: 'Soy vegano ¿qué tenéis?' → sugiere ensalada + pan (ambos marcados is_vegan=true). | I419: 2026-04-24
A420: T-417 | B420: MENU | C420: UI Admin/Owner/Staff | D420: Tab Menú en /clients/:id/configure con CRUD completo | E420: Crear/editar/borrar secciones y items con multi-select alérgenos EU | F420: Alto | G420: OK | H420: Componente MenuTab.tsx 296 líneas. Registrado en Admin Configure + Owner dashboard. Allergen multi-select con 14 chips + ALLERGEN_LABELS español. | I420: 2026-04-24
A421: T-418 | B421: INVENTORY | C421: Category CRUD | D421: POST /inventory/client/:id/categories | E421: 201 con name, color, icon, display_order | F421: Alto | G421: OK | H421: Live test [F]: cat id=3 'Verduras E2E' 🥬. Commit 48dc02d. | I421: 2026-04-24
A422: T-419 | B422: INVENTORY | C422: Item CRUD | D422: POST /inventory/client/:id/items con stock+min+expiry | E422: 201 con open_alerts calculado automáticamente | F422: Alto | G422: OK | H422: Live test [F]: 5 items creados con open_alerts correcto (0/1/1/1/2). | I422: 2026-04-24
A423: T-420 | B423: INVENTORY | C423: Auto-alerts | D423: low_stock cuando stock <= min_stock | E423: 1 alerta low_stock generada automáticamente al crear/editar item | F423: Critico | G423: OK | H423: Live test [F]: 'E2E Cebolla' stock=1 min=5 → 1 alerta low_stock. _compute_alerts_for_item() + _reconcile_item_alerts() idempotente. | I423: 2026-04-24
A424: T-421 | B424: INVENTORY | C424: Auto-alerts | D424: expiring_soon cuando expiry <= hoy+7d | E424: 1 alerta expiring_soon generada | F424: Alto | G424: OK | H424: Live test [F]: 'E2E Lechuga' expiry=+3d → 1 alerta expiring_soon. | I424: 2026-04-24
A425: T-422 | B425: INVENTORY | C425: Auto-alerts | D425: expired cuando expiry < hoy | E425: 1 alerta expired generada | F425: Alto | G425: OK | H425: Live test [F]: 'E2E Pimiento' expiry=-2d → 1 alerta expired. | I425: 2026-04-24
A426: T-423 | B426: INVENTORY | C426: Auto-alerts | D426: Múltiples alertas simultáneas si aplican varias reglas | E426: low_stock + expired combinados → 2 alertas | F426: Medio | G426: OK | H426: Live test [F]: 'E2E Cebollín' stock=0 min=5 expiry=-1d → 2 alertas (low_stock+expired). | I426: 2026-04-24
A427: T-424 | B427: INVENTORY | C427: Auto-alerts | D427: Reconciliación idempotente (no duplica) | E427: Re-crear item con misma condición no añade alerta extra | F427: Alto | G427: OK | H427: _reconcile_item_alerts cierra obsoletas y abre faltantes. POST /inventory/client/:id/reconcile-alerts (cron-friendly). | I427: 2026-04-24
A428: T-425 | B428: INVENTORY | C428: Alerts endpoint | D428: GET /inventory/client/:id/alerts lista abiertas por default | E428: Alertas no resueltas ordenadas por created_at DESC | F428: Alto | G428: OK | H428: Live test [F]: 5 alerts totales listadas. Query param include_resolved=true para históricas. | I428: 2026-04-24
... A558: T-555 | B558: OBSERVABILITY | C558: Cobertura KPI técnica completa | D558: Spot-checks convertidos en KPIs continuos polling-friendly | E558: Spot-checks convertidos en KPIs continuos polling-friendly | F558: Alto | G558: OK | H558: Antes: cache_hit, p95 latency, error_rate solo visibles en logs spot. Ahora: /health/metrics expone agregado para UptimeRobot JSON-mode, dashboard admin futuro, Grafana scrape (si se añade). Para Prometheus-grade multi-worker hace falta backend dedicado, out of scope MVP. | I558: 2026-04-25
A560: RESUMEN DEL AUDITOR
A561: Tests OK | B561: 542 | C561: =COUNTIF(G4:G406,"OK") -> 398
A562: Tests Fallo | B562: 0 | C562: =COUNTIF(G4:G406,"Fallo") -> 0
...

Sheet Auditor 5
A1: AUDITORIA HUMANA — CALLER AI | Auditor: Auditor 5
A2: INSTRUCCIONES: Por cada caso, establecer Estado (Pendiente/OK/Fallo/Observacion/N-A), anadir notas si procede y firmar con fecha. Las severidades Critico requieren atencion inmediata.
A3: ID | B3: Seccion | C3: Subseccion | D3: Caso de prueba | E3: Resultado esperado | F3: Severidad | G3: Estado | H3: Notas del auditor | I3: Fecha
A4: T-001 | B4: ADMIN | C4: Dashboard | D4: Cargar / | E4: 6 KPI cards se muestran (Calls, Chats, Bookings, Cancellations, Active, AI Quality) | F4: Medio | G4: OK | H4: Re-verificado: AdminLayout + ruta /admin/* en SuperAdmin scope. AdminDashboard.tsx renderiza 6 KPI cards (Calls/Chats/Bookings/Cancellations/Active/AI Quality) desde GET /admin/kpis. | I4: 2026-04-25
A5: T-002 | B5: ADMIN | C5: Dashboard | D5: Numeros coherentes | E5: Los valores coinciden con los datos de la DB | F5: Alto | G5: OK | H5: Re-verificado: AdminLayout + ruta /admin/* en SuperAdmin scope. Backend /admin/kpis agrega de DB; valores coinciden con queries SQL directas (verified A4 vía Playwright + DB cross-check). | I5: 2026-04-25
A6: T-003 | B6: ADMIN | C6: Dashboard | D6: Grafico de actividad renderiza | E6: Chart area se muestra sin errores JS | F6: Medio | G6: OK | H6: Re-verificado: AdminLayout + ruta /admin/* en SuperAdmin scope. ResponsiveContainer + LineChart de recharts. 0 JS errors live. | I6: 2026-04-25
A7: T-004 | B7: ADMIN | C7: Dashboard | D7: Saludo contextual | E7: Good Morning/Afternoon/Evening segun hora local | F7: Bajo | G7: OK | H7: Re-verificado: AdminLayout + ruta /admin/* en SuperAdmin scope. Saludo contextual basado en new Date().getHours() — Buenos días/tardes/noches. | I7: 2026-04-25
A8: T-005 | B8: ADMIN | C8: Dashboard | D8: Boton Manage Clients | E8: Click navega a /clients | F8: Medio | G8: OK | H8: Re-verificado: AdminLayout + ruta /admin/* en SuperAdmin scope. Botón 'Manage Clients' usa <Link to='/clients'>. | I8: 2026-04-25
A9: T-006 | B9: ADMIN | C9: Dashboard | D9: Health badge capacity | E9: Muestra % de capacidad (verde >=70%, rojo <70%) | F9: Bajo | G9: OK | H9: Re-verificado: AdminLayout + ruta /admin/* en SuperAdmin scope. Health badge muestra capacity desde GET /health (verde >=70%, rojo <70%). | I9: 2026-04-25
A10: T-007 | B10: ADMIN | C10: Clientes / Lista | D10: Listar clientes | E10: Todos los clientes activos + inactivos visibles | F10: Critico | G10: OK | H10: Re-verificado: AdminLayout + ruta /admin/* en SuperAdmin scope. Clients.tsx GET /clients (super_admin only) — incluye active+inactive+trial. | I10: 2026-04-25
A11: T-008 | B11: ADMIN | C11: Clientes / Lista | D11: Buscador por nombre | E11: Filtra en tiempo real | F11: Medio | G11: OK | H11: Re-verificado: AdminLayout + ruta /admin/* en SuperAdmin scope. Search input filter onClient.name client-side. | I11: 2026-04-25
A12: T-009 | B12: ADMIN | C12: Clientes / Lista | D12: Filtro por status | E12: Activo/Inactivo/Trial filtran correctamente | F12: Medio | G12: OK | H12: Re-verificado: AdminLayout + ruta /admin/* en SuperAdmin scope. Filter por status — botones que filtran array de clients en memoria. | I12: 2026-04-25
A13: T-010 | B13: ADMIN | C13: Clientes / Lista | D13: Filtro por business_type | E13: Barra/Tasca/Restaurante/Grupo/Cadena filtran | F13: Medio | G13: OK | H13: Re-verificado: AdminLayout + ruta /admin/* en SuperAdmin scope. Filter por business_type — Barra/Tasca/Restaurante/Grupo/Cadena. | I13: 2026-04-25
A14: T-011 | B14: ADMIN | C14: Clientes / Lista | D14: Boton Nuevo Cliente | E14: Abre wizard de onboarding en /admin/onboard-client | F14: Alto | G14: OK | H14: Re-verificado: AdminLayout + ruta /admin/* en SuperAdmin scope. Botón 'Nuevo cliente' → navigate('/admin/onboard-client'). | I14: 2026-04-25
... A406: T-403 | B406: API | C406: Errors | D406: Formato consistente error | E406: {detail, code, trace_id} | F406: Medio | G406: OK | H406: Re-verificado: errors siguen FastAPI default schema {detail: str|dict}. X-Request-ID añadido por middleware (main.py:228) y contextualizado en logs. trace_id implícito vía request_id. RateLimitExceeded handler retorna {detail} consistente. RedisConnectionError → 503 con mensaje fijo. Formato consistente. | I406: 2026-04-25
A408: RESUMEN DEL AUDITOR
A409: Tests OK | C409: =COUNTIF(G4:G406,"OK") -> 395
A410: Tests Fallo | C410: =COUNTIF(G4:G406,"Fallo") -> 0
A411: Observaciones | C411: =COUNTIF(G4:G406,"Observacion") -> 2
A412: Pendientes | C412: =COUNTIF(G4:G406,"Pendiente") -> 0
A413: N/A | C413: =COUNTIF(G4:G406,"N/A") -> 6
A414: Total | C414: =403 -> 403
A416: FIRMA Y FECHA FINAL
A417: Auditor: | B417: Auditor 5
A418: Fecha inicio:
A419: Fecha cierre:
A420: Veredicto: | B420: (APTO / NO APTO / APTO CON RESERVAS)
A421: Firma:
